<?xml version="1.0"?>
<robot name="my_arm">

  <material name="blue">
    <color rgba="0 0 .8 1"/>
  </material>
  <material name="black">
    <color rgba="0 0 0 1"/>
  </material>
  <material name="white">
    <color rgba="1 1 1 1"/>
  </material>

  <link name="base_link" />

  <link name="base">
    <visual>
      <origin xyz="0 0 0" rpy="0 0 0"/>
      <geometry>
        <mesh filename="package://my_arm/meshes/1.stl" scale="0.001 0.001 0.001"/>
      </geometry>
      <material name ="white"/>
    </visual>
    <collision>
      <origin xyz="0 0 0" rpy="0 0 0"/>
      <geometry>
        <mesh filename="package://my_arm/meshes/1.stl" scale="0.001 0.001 0.001"/>
      </geometry>
    </collision>
    <inertial>
      <origin rpy="0 0 0" xyz="0.004190989 0.00646279 0.063222557"/>
      <mass value="1"/>
    <inertia ixx="42671.665152" ixy="-170.122720" ixz="-2806.081792" iyy="45598.126080" iyz="-166.363328" izz="66783.621120"/>
    </inertial>
  </link>

  <link name="elbow_link">
    <visual>
      <origin xyz="-0.062 -0.051 0.014" rpy="0 0 0"/>
      <geometry>
        <mesh filename="package://my_arm/meshes/2.stl" scale="0.001 0.001 0.001"/>
      </geometry>
      <material name ="blue"/>
    </visual>
    <collision>
      <origin xyz="-0.062 -0.051 0.014" rpy="0 0 0"/>
      <geometry>
        <mesh filename="package://my_arm/meshes/2.stl" scale="0.001 0.001 0.001"/>
      </geometry>
    </collision>
    <inertial>
      <origin rpy="0 0 0" xyz="0.052649582 0.057137184 0.133373611"/>
      <mass value="1"/>
    <inertia ixx="28872.232960" ixy="15.032029" ixz="716.172992" iyy="27957.540864" iyz="8.286923" izz="6728.539648"/>
    </inertial>
  </link>

  <link name="wrist_link">
    <visual>
      <origin xyz="-0.001 -0.064 0" rpy="0 0 0"/>
      <geometry>
        <mesh filename="package://my_arm/meshes/3.stl" scale="0.001 0.001 0.001"/>
      </geometry>
      <material name ="white"/>
    </visual>
    <collision>
      <origin xyz="-0.001 -0.064 0" rpy="0 0 0"/>
      <geometry>
        <mesh filename="package://my_arm/meshes/3.stl" scale="0.001 0.001 0.001"/>
      </geometry>
    </collision>
    <inertial>
      <origin rpy="0 0 0" xyz="-0.008036790 0.031757582 0.188686127"/>
      <mass value="1"/>
    <inertia ixx="47496.544256" ixy="-12.229211" ixz="1797.142656" iyy="48284.073984" iyz="20.978956" izz="2536.107264"/>
    </inertial>
  </link>

  <link name="hand_link">
    <visual>
      <origin xyz="-0.037 -0.001 0.092" rpy="0 0 0"/>
      <geometry>
        <mesh filename="package://my_arm/meshes/4.stl" scale="0.001 0.001 0.001"/>
      </geometry>
      <material name ="blue"/>
    </visual>
    <collision>
      <origin xyz="-0.037 -0.001 0.092" rpy="0 0 0"/>
      <geometry>
        <mesh filename="package://my_arm/meshes/4.stl" scale="0.001 0.001 0.001"/>
      </geometry>
    </collision>
    <inertial>
      <origin rpy="0 0 0" xyz="0.028896175 0.036595043 0.087612099"/>
      <mass value="1"/>
    <inertia ixx="1867.552768" ixy="-0.000095417305" ixz="0.195820593750" iyy="1840.582272" iyz="-0.000011109801" izz="451.477600"/>
    </inertial>
  </link>

  <link name="gripper_link">
    <visual>
      <origin xyz="-0.03 -0.037 0" rpy="0 0 0"/>
      <geometry>
        <mesh filename="package://my_arm/meshes/5.stl" scale="0.001 0.001 0.001"/>
      </geometry>
      <material name ="white"/>
    </visual>
    <collision>
      <origin xyz="-0.03 -0.037 0" rpy="0 0 0"/>
      <geometry>
        <mesh filename="package://my_arm/meshes/5.stl" scale="0.001 0.001 0.001"/>
      </geometry>
    </collision>
    <inertial>
      <origin rpy="0 0 0" xyz="0.028896175 0.036595043 0.087612099"/>
      <mass value="1"/>
    <inertia ixx="1867.552768" ixy="-0.000095417305" ixz="0.195820593750" iyy="1840.582272" iyz="-0.000011109801" izz="451.477600"/>
    </inertial>
  </link>

  <link name="finger_link1">
    <visual>
      <origin xyz="0 0 0" rpy="0 0 0"/>
      <geometry>
        <mesh filename="package://my_arm/meshes/6.stl" scale="0.001 0.001 0.001"/>
      </geometry>
      <material name ="blue"/>
    </visual>
    <collision>
      <origin xyz="0 0 0" rpy="0 0 0"/>
      <geometry>
        <mesh filename="package://my_arm/meshes/6.stl" scale="0.001 0.001 0.001"/>
      </geometry>
    </collision>
    <inertial>
      <origin rpy="0 0 0" xyz="0.010424928 0.016705904 0.035355106"/>
      <mass value="1"/>
    <inertia ixx="9.274621" ixy="-0.000133487228" ixz="-0.014046430664" iyy="9.224906" iyz="-0.0762759375" izz="1.227274"/>
    </inertial>
  </link>

  <link name="finger_link2">
    <visual>
      <origin xyz="0 0 0" rpy="0 0 0"/>
      <geometry>
        <mesh filename="package://my_arm/meshes/7.stl" scale="0.001 0.001 0.001"/>
      </geometry>
      <material name ="blue"/>
    </visual>
    <collision>
      <origin xyz="0 0 0" rpy="0 0 0"/>
      <geometry>
        <mesh filename="package://my_arm/meshes/7.stl" scale="0.001 0.001 0.001"/>
      </geometry>
    </collision>
    <inertial>
      <origin rpy="0 0 0" xyz="0.010432852 -0.009562554 0.039894608"/>
      <mass value="1"/>
    <inertia ixx="9.274626" ixy="0.000133295685" ixz="-0.014046378906" iyy="9.224907" iyz="0.076274" izz="1.227275"/>
    </inertial>
  </link>

  <joint name="base2base_joint" type="continuous">
    <parent link="base_link" />
    <child link="base" />
    <origin xyz="0.137 0.137 0" rpy="0 0 0" />
    <axis xyz="0 0 1" />
  </joint>

  <joint name="base_joint" type="revolute">
    <parent link="base" />
    <child link="elbow_link" />
    <limit effort="30" velocity="1.0" lower="-1.570795" upper="1.570795" />
    <origin xyz="0.101 0 0.207" rpy="0 0 0" />
    <axis xyz="0 1 0" />
  </joint>

  <joint name="elbow_joint" type="revolute">
    <parent link="elbow_link" />
    <child link="wrist_link" />
    <limit effort="30" velocity="1.0" lower="-1.570795" upper="1.570795" />
    <origin xyz="-0.014 0.037 0.341" rpy="0 0 0" />
    <axis xyz="0 1 0" />
  </joint>

  <joint name="wrist_joint" type="revolute">
    <parent link="wrist_link" />
    <child link="hand_link" />
    <limit effort="30" velocity="1.0" lower="-1.570795" upper="1.570795" />
    <origin xyz="-0.015 -0.088 0.398" rpy="0 0 0" />
    <axis xyz="0 1 0" />
  </joint>

  <joint name="hand_joint" type="continuous">
    <parent link="hand_link" />
    <child link="gripper_link" />
    <limit effort="30" velocity="1.0" lower="-1.570795" upper="1.570795" />
    <origin xyz="0.0 0.056 0.113" rpy="0 0 0" />
    <axis xyz="0 0 1" />
  </joint>

  <joint name="finger_joint1" type="revolute">
    <parent link="gripper_link" />
    <child link="finger_link1" />
    <limit effort="30" velocity="1.0" lower="-1.570795" upper="1.570795" />
    <origin xyz="-0.01 0.036 0.184" rpy="0 0 0" />
    <axis xyz="1 0 0" />
  </joint>

  <joint name="finger_joint2" type="revolute">
    <parent link="gripper_link" />
    <child link="finger_link2" />
    <limit effort="30" velocity="1.0" lower="-1.570795" upper="1.570795" />
    <origin xyz="-0.01 -0.037 0.184" rpy="0 0 0" />
    <axis xyz="1 0 0" />
  </joint>


</robot>
