<?xml version="1.0"?>
<robot name="my_arm">
  <property name="M_PI" value="3.1415926535897931" /> 
  <property name="cam_px" value="0.35" />
  <property name="cam_py" value="0.137" />
  <property name="cam_pz" value="0.1" />

  <material name="blue">
    <color rgba="0 0 .8 1"/>
  </material>
  <material name="black">
    <color rgba="0 0 0 1"/>
  </material>
  <material name="white">
    <color rgba="1 1 1 1"/>
  </material>

  <link name="world"/>

  <link name="support">
    <visual>
        <origin xyz="0 0 0.75" rpy="0 0 0"/>
	<geometry>
	  <box size="0.1 0.1 1.5"/>
	</geometry>
	<material name ="blue"/>
    </visual>
    <collision>
        <origin xyz="0 0 0.75" rpy="0 0 0"/>
	<geometry>
	  <box size="0.1 0.1 1.5"/>
	</geometry>
    </collision>
    <inertial>
      <mass value="0.001"/>
    <inertia ixx="0.01" ixy="0" ixz="0" iyy="0.01" iyz="0" izz="0.01"/>
    </inertial>
  </link>


  <link name="base">
    <visual>
      <origin xyz="0 0 0" rpy="0 0 0"/>
      <geometry>
        <mesh filename="package://my_arm/meshes/1.stl" scale="0.001 0.001 0.001"/>
      </geometry>
      <material name ="white"/>
    </visual>
    <collision>
      <origin xyz="0 0 0" rpy="0 0 0"/>
      <geometry>
        <mesh filename="package://my_arm/meshes/1.stl" scale="0.001 0.001 0.001"/>
      </geometry>
    </collision>
    <inertial>
      <origin rpy="0 0 0" xyz="0.004190989 0.00646279 0.063222557"/>
      <mass value="0.001"/>
    <inertia ixx="0.0125" ixy="0" ixz="0" iyy="0.009" iyz="0" izz="0.009"/>
    </inertial>
  </link>

  <link name="elbow_link">
    <visual>
      <origin xyz="-0.062 -0.051 0.014" rpy="0 0 0"/>
      <geometry>
        <mesh filename="package://my_arm/meshes/2.stl" scale="0.001 0.001 0.001"/>
      </geometry>
      <material name ="blue"/>
    </visual>
    <collision>
      <origin xyz="-0.062 -0.051 0.014" rpy="0 0 0"/>
      <geometry>
        <mesh filename="package://my_arm/meshes/2.stl" scale="0.001 0.001 0.001"/>
      </geometry>
    </collision>
    <inertial>
      <origin rpy="0 0 0" xyz="0.052649582 0.057137184 0.133373611"/>
      <mass value="0.001"/>
    <inertia ixx="0.029" ixy="0" ixz="0" iyy="0.03198" iyz="0" izz="0.220"/>
    </inertial>
  </link>

  <link name="wrist_link">
    <visual>
      <origin xyz="-0.001 -0.064 0" rpy="0 0 0"/>
      <geometry>
        <mesh filename="package://my_arm/meshes/3.stl" scale="0.001 0.001 0.001"/>
      </geometry>
      <material name ="white"/>
    </visual>
    <collision>
      <origin xyz="-0.001 -0.064 0" rpy="0 0 0"/>
      <geometry>
        <mesh filename="package://my_arm/meshes/3.stl" scale="0.001 0.001 0.001"/>
      </geometry>
    </collision>
    <inertial>
      <origin rpy="0 0 0" xyz="-0.008036790 0.031757582 0.188686127"/>
      <mass value="0.001"/>
    <inertia ixx="0.015" ixy="0" ixz="0" iyy="0.238481" iyz="0" izz="0.245072"/>
    </inertial>
  </link>

  <link name="hand_link">
    <visual>
      <origin xyz="-0.037 -0.001 0.092" rpy="0 0 0"/>
      <geometry>
        <mesh filename="package://my_arm/meshes/4.stl" scale="0.001 0.001 0.001"/>
      </geometry>
      <material name ="blue"/>
    </visual>
    <collision>
      <origin xyz="-0.037 -0.001 0.092" rpy="0 0 0"/>
      <geometry>
        <mesh filename="package://my_arm/meshes/4.stl" scale="0.001 0.001 0.001"/>
      </geometry>
    </collision>
    <inertial>
      <origin rpy="0 0 0" xyz="0.028896175 0.036595043 0.087612099"/>
      <mass value="0.001"/>
    <inertia ixx="0.01901" ixy="0" ixz="0" iyy="0.03497" iyz="0" izz="0.028442"/>
    </inertial>
  </link>

  <link name="gripper_link">
    <visual>
      <origin xyz="-0.03 -0.037 0" rpy="0 0 0"/>
      <geometry>
        <mesh filename="package://my_arm/meshes/5.stl" scale="0.001 0.001 0.001"/>
      </geometry>
      <material name ="white"/>
    </visual>
    <collision>
      <origin xyz="-0.03 -0.037 0" rpy="0 0 0"/>
      <geometry>
        <mesh filename="package://my_arm/meshes/5.stl" scale="0.001 0.001 0.001"/>
      </geometry>
    </collision>
    <inertial>
      <origin rpy="0 0 0" xyz="0.028896175 0.036595043 0.087612099"/>
      <mass value="0.0005"/>
    <inertia ixx="0.008693" ixy="0" ixz="0" iyy="0.039554" iyz="0" izz="0.037589"/>
    </inertial>
  </link>

  <link name="finger_link1">
    <visual>
      <origin xyz="0 0 0" rpy="0 0 0"/>
      <geometry>
        <mesh filename="package://my_arm/meshes/6.stl" scale="0.001 0.001 0.001"/>
      </geometry>
      <material name ="blue"/>
    </visual>
    <collision>
      <origin xyz="0 0 0" rpy="0 0 0"/>
      <geometry>
        <mesh filename="package://my_arm/meshes/6.stl" scale="0.001 0.001 0.001"/>
      </geometry>
    </collision>
    <inertial>
      <origin rpy="0 0 0" xyz="0.010424928 0.016705904 0.035355106"/>
      <mass value="0.0005"/>
    <inertia ixx="0.00125" ixy="0" ixz="0" iyy="0.007345" iyz="0" izz="0.007002"/>
    </inertial>
  </link>

  <link name="finger_link2">
    <visual>
      <origin xyz="0 0 0" rpy="0 0 0"/>
      <geometry>
        <mesh filename="package://my_arm/meshes/7.stl" scale="0.001 0.001 0.001"/>
      </geometry>
      <material name ="blue"/>
    </visual>
    <collision>
      <origin xyz="0 0 0" rpy="0 0 0"/>
      <geometry>
        <mesh filename="package://my_arm/meshes/7.stl" scale="0.001 0.001 0.001"/>
      </geometry>
    </collision>
    <inertial>
      <origin rpy="0 0 0" xyz="0.010432852 -0.009562554 0.039894608"/>
      <mass value="1"/>
    <inertia ixx="0.00125" ixy="0" ixz="0" iyy="0.007345" iyz="0" izz="0.007002"/>
    </inertial>
  </link>

  <link name="end">
    <inertial>
      <mass value="0.001"/>
    <inertia ixx="0.01" ixy="0" ixz="0" iyy="0.01" iyz="0" izz="0.01"/>
    </inertial>
  </link>

  <joint name="support_joint" type="fixed">
    <parent link="world" />
    <child link="support" />
    <origin xyz="0 0 0" rpy="0 0 0" />
    <axis xyz="0 0 1" />
  </joint>

  <joint name="base2base_joint" type="continuous">
    <parent link="support" />
    <child link="base" />
    <origin xyz="0 -0.05 1.3" rpy="1.5707963 0 0" />
    <axis xyz="0 0 1" />
  </joint>

  <joint name="base_joint" type="revolute">
    <parent link="base" />
    <child link="elbow_link" />
    <limit effort="30" velocity="1.0" lower="-1.570795" upper="1.570795" />
    <origin xyz="0.101 0 0.207" rpy="0 0 0" />
    <axis xyz="0 1 0" />
  </joint>

  <joint name="elbow_joint" type="revolute">
    <parent link="elbow_link" />
    <child link="wrist_link" />
    <limit effort="30" velocity="1.0" lower="-3.1415926" upper="3.1415926" />
    <origin xyz="-0.014 0.037 0.341" rpy="0 0 0" />
    <axis xyz="0 1 0" />
  </joint>

  <joint name="wrist_joint" type="revolute">
    <parent link="wrist_link" />
    <child link="hand_link" />
    <limit effort="30" velocity="1.0" lower="-3.1415926" upper="3.1415926" />
    <origin xyz="-0.015 -0.088 0.398" rpy="0 0 0" />
    <axis xyz="0 1 0" />
  </joint>

  <joint name="hand_joint" type="continuous">
    <parent link="hand_link" />
    <child link="gripper_link" />
    <limit effort="30" velocity="1.0" lower="-1.570795" upper="1.570795" />
    <origin xyz="0.0 0.056 0.113" rpy="0 0 0" />
    <axis xyz="0 0 1" />
  </joint>

  <joint name="end_joint" type="revolute">
    <parent link="gripper_link" />
    <child link="end" />
    <origin xyz="0 0 0.184" rpy="0 0 0" />
    <limit effort="30" velocity="1.0" lower="-1.570795" upper="1.570795" />
    <axis xyz="0 1 0" />
  </joint>

  <joint name="finger_joint1" type="revolute">
    <parent link="gripper_link" />
    <child link="finger_link1" />
    <limit effort="30" velocity="1.0" lower="-1.570795" upper="1.570795" />
    <origin xyz="-0.01 0.036 0.184" rpy="0 0 0" />
    <axis xyz="1 0 0" />
  </joint>

  <joint name="finger_joint2" type="revolute">
    <parent link="gripper_link" />
    <child link="finger_link2" />
    <limit effort="30" velocity="1.0" lower="-1.570795" upper="1.570795" />
    <origin xyz="-0.01 -0.037 0.184" rpy="0 0 0" />
    <axis xyz="1 0 0" />
  </joint>


  <transmission name="tran1">
    <type>transmission_interface/SimpleTransmission</type>
    <joint name="base2base_joint">
      <hardwareInterface>hardware_interface/PositionJointInterface</hardwareInterface>
    </joint>
    <actuator name="motor1">
      <mechanicalReduction>1</mechanicalReduction>
    </actuator>
  </transmission>

  <transmission name="tran2">
    <type>transmission_interface/SimpleTransmission</type>
    <joint name="base_joint">
      <hardwareInterface>hardware_interface/PositionJointInterface</hardwareInterface>
    </joint>
    <actuator name="motor2">
      <mechanicalReduction>1</mechanicalReduction>
    </actuator>
  </transmission>

  <transmission name="tran3">
    <type>transmission_interface/SimpleTransmission</type>
    <joint name="elbow_joint">
      <hardwareInterface>hardware_interface/PositionJointInterface</hardwareInterface>
    </joint>
    <actuator name="motor3">
      <mechanicalReduction>1</mechanicalReduction>
    </actuator>
  </transmission>

  <transmission name="tran4">
    <type>transmission_interface/SimpleTransmission</type>
    <joint name="wrist_joint">
      <hardwareInterface>hardware_interface/PositionJointInterface</hardwareInterface>
    </joint>
    <actuator name="motor4">
      <mechanicalReduction>1</mechanicalReduction>
    </actuator>
  </transmission>

  <transmission name="tran5">
    <type>transmission_interface/SimpleTransmission</type>
    <joint name="hand_joint">
      <hardwareInterface>hardware_interface/PositionJointInterface</hardwareInterface>
    </joint>
    <actuator name="motor5">
      <mechanicalReduction>1</mechanicalReduction>
    </actuator>
  </transmission>

  <transmission name="tran6">
    <type>transmission_interface/SimpleTransmission</type>
    <joint name="finger_joint1">
      <hardwareInterface>hardware_interface/PositionJointInterface</hardwareInterface>
    </joint>
    <actuator name="motor6">
      <mechanicalReduction>1</mechanicalReduction>
    </actuator>
  </transmission>

  <transmission name="tran7">
    <type>transmission_interface/SimpleTransmission</type>
    <joint name="finger_joint2">
      <hardwareInterface>hardware_interface/PositionJointInterface</hardwareInterface>
    </joint>
    <actuator name="motor7">
      <mechanicalReduction>1</mechanicalReduction>
    </actuator>
  </transmission>

  <transmission name="tran8">
    <type>transmission_interface/SimpleTransmission</type>
    <joint name="end_joint">
      <hardwareInterface>hardware_interface/PositionJointInterface</hardwareInterface>
    </joint>
    <actuator name="motor8">
      <mechanicalReduction>1</mechanicalReduction>
    </actuator>
  </transmission>
<gazebo>
  <plugin name="gazebo_ros_control" filename="libgazebo_ros_control.so">
  </plugin>
</gazebo>


<gazebo>
   <plugin name="gazebo_grasp_fix" filename="libgazebo_grasp_fix.so">
        <arm>
           <arm_name>my_arm</arm_name>
           <palm_link> gripper_link  </palm_link>
           <gripper_link> finger_link1 </gripper_link>
           <gripper_link> finger_link2 </gripper_link>
        </arm>
       <forces_angle_tolerance>100</forces_angle_tolerance>
       <update_rate>4</update_rate>
       <grip_count_threshold>4</grip_count_threshold>
       <max_grip_count>8</max_grip_count>
       <release_tolerance>0.005</release_tolerance>
       <disable_collisions_on_attach>false</disable_collisions_on_attach>
       <contact_topic>__default_topic__</contact_topic>
    </plugin>
</gazebo>

 
    <link name="camera_link">
    <visual>
     <origin xyz="0 0 0" rpy="0 0 0"/>
      <geometry>
       <mesh filename="package://my_arm/meshes/kinect.dae"/>
      </geometry>
    </visual>
	  <collision>
      <origin xyz="0.0 0.0 0.0" rpy="0 0 0"/>
	    <geometry>
	      <box size="0.07271 0.27794 0.073"/>
	    </geometry>
	  </collision>
    <inertial>
      <mass value="0.001" />
      <origin xyz="0 0 0" />
      <inertia ixx="0.0001" ixy="0.0" ixz="0.0"
               iyy="0.0001" iyz="0.0"
               izz="0.0001" />
    </inertial>
  </link>
  <joint name="camera_joint" type="fixed">
    <origin xyz="0 0 1.55" rpy="0 0 0"/>
    <parent link="world"/>
    <child link="camera_link"/>
  </joint> 	  
 
  <gazebo reference="camera_link">  
      <sensor name="camera" type="depth">
        <update_rate>20</update_rate>
        <camera>
          <horizontal_fov>1.047198</horizontal_fov>
          <image>
            <width>640</width>
            <height>480</height>
            <format>R8G8B8</format>
          </image>
          <clip>
            <near>0.05</near>
            <far>3</far>
          </clip>
        </camera>
        <plugin name="camera_plugin" filename="libgazebo_ros_openni_kinect.so">
          <baseline>0.2</baseline>
          <alwaysOn>true</alwaysOn>
          <!-- Keep this zero, update_rate in the parent <sensor> tag
            will control the frame rate. -->
          <updateRate>0.0</updateRate>
          <cameraName>camera_ir</cameraName>
          <imageTopicName>/camera/depth/image_raw</imageTopicName>
          <cameraInfoTopicName>/camera/depth/camera_info</cameraInfoTopicName>
          <depthImageTopicName>/camera/depth/image_raw</depthImageTopicName>
          <depthImageInfoTopicName>/camera/depth/camera_info</depthImageInfoTopicName>
          <pointCloudTopicName>/camera/depth/points</pointCloudTopicName>
          <frameName>camera_link</frameName>
          <pointCloudCutoff>0.05</pointCloudCutoff>
          <distortionK1>0</distortionK1>
          <distortionK2>0</distortionK2>
          <distortionK3>0</distortionK3>
          <distortionT1>0</distortionT1>
          <distortionT2>0</distortionT2>
          <CxPrime>0</CxPrime>
          <Cx>0</Cx>
          <Cy>0</Cy>
          <focalLength>0</focalLength>
          <hackBaseline>0</hackBaseline>
        </plugin>
      </sensor>
    </gazebo>

</robot>
