<?xml version="1.0"?>
<robot name="my_arm">

  <material name="blue">
    <color rgba="0 0 .8 1"/>
  </material>
  <material name="black">
    <color rgba="0 0 0 1"/>
  </material>
  <material name="white">
    <color rgba="1 1 1 1"/>
  </material>

  <link name="world"/>

  <link name="base">
    <visual>
      <origin xyz="0 0 0" rpy="0 0 0"/>
      <geometry>
        <mesh filename="package://my_arm/meshes/1.stl" scale="0.001 0.001 0.001"/>
      </geometry>
      <material name ="white"/>
    </visual>
    <collision>
      <origin xyz="0 0 0" rpy="0 0 0"/>
      <geometry>
        <mesh filename="package://my_arm/meshes/1.stl" scale="0.001 0.001 0.001"/>
      </geometry>
    </collision>
    <inertial>
      <origin rpy="0 0 0" xyz="0.004190989 0.00646279 0.063222557"/>
      <mass value="1"/>
    <inertia ixx="0.0125" ixy="0" ixz="0" iyy="0.009" iyz="0" izz="0.009"/>
    </inertial>
  </link>

  <link name="elbow_link">
    <visual>
      <origin xyz="-0.062 -0.051 0.014" rpy="0 0 0"/>
      <geometry>
        <mesh filename="package://my_arm/meshes/2.stl" scale="0.001 0.001 0.001"/>
      </geometry>
      <material name ="blue"/>
    </visual>
    <collision>
      <origin xyz="-0.062 -0.051 0.014" rpy="0 0 0"/>
      <geometry>
        <mesh filename="package://my_arm/meshes/2.stl" scale="0.001 0.001 0.001"/>
      </geometry>
    </collision>
    <inertial>
      <origin rpy="0 0 0" xyz="0.052649582 0.057137184 0.133373611"/>
      <mass value="1"/>
    <inertia ixx="0.029" ixy="0" ixz="0" iyy="0.03198" iyz="0" izz="0.220"/>
    </inertial>
  </link>

  <link name="wrist_link">
    <visual>
      <origin xyz="-0.001 -0.064 0" rpy="0 0 0"/>
      <geometry>
        <mesh filename="package://my_arm/meshes/3.stl" scale="0.001 0.001 0.001"/>
      </geometry>
      <material name ="white"/>
    </visual>
    <collision>
      <origin xyz="-0.001 -0.064 0" rpy="0 0 0"/>
      <geometry>
        <mesh filename="package://my_arm/meshes/3.stl" scale="0.001 0.001 0.001"/>
      </geometry>
    </collision>
    <inertial>
      <origin rpy="0 0 0" xyz="-0.008036790 0.031757582 0.188686127"/>
      <mass value="1"/>
    <inertia ixx="0.015" ixy="0" ixz="0" iyy="0.238481" iyz="0" izz="0.245072"/>
    </inertial>
  </link>

  <link name="hand_link">
    <visual>
      <origin xyz="-0.037 -0.001 0.092" rpy="0 0 0"/>
      <geometry>
        <mesh filename="package://my_arm/meshes/4.stl" scale="0.001 0.001 0.001"/>
      </geometry>
      <material name ="blue"/>
    </visual>
    <collision>
      <origin xyz="-0.037 -0.001 0.092" rpy="0 0 0"/>
      <geometry>
        <mesh filename="package://my_arm/meshes/4.stl" scale="0.001 0.001 0.001"/>
      </geometry>
    </collision>
    <inertial>
      <origin rpy="0 0 0" xyz="0.028896175 0.036595043 0.087612099"/>
      <mass value="1"/>
    <inertia ixx="0.01901" ixy="0" ixz="0" iyy="0.03497" iyz="0" izz="0.028442"/>
    </inertial>
  </link>

  <link name="gripper_link">
    <visual>
      <origin xyz="-0.03 -0.037 0" rpy="0 0 0"/>
      <geometry>
        <mesh filename="package://my_arm/meshes/5.stl" scale="0.001 0.001 0.001"/>
      </geometry>
      <material name ="white"/>
    </visual>
    <collision>
      <origin xyz="-0.03 -0.037 0" rpy="0 0 0"/>
      <geometry>
        <mesh filename="package://my_arm/meshes/5.stl" scale="0.001 0.001 0.001"/>
      </geometry>
    </collision>
    <inertial>
      <origin rpy="0 0 0" xyz="0.028896175 0.036595043 0.087612099"/>
      <mass value="1"/>
    <inertia ixx="0.008693" ixy="0" ixz="0" iyy="0.039554" iyz="0" izz="0.037589"/>
    </inertial>
  </link>

  <joint name="base2base_joint" type="continuous">
    <parent link="world" />
    <child link="base" />
    <origin xyz="0.137 0.137 0" rpy="0 0 0" />
    <axis xyz="0 0 1" />
  </joint>

  <joint name="base_joint" type="revolute">
    <parent link="base" />
    <child link="elbow_link" />
    <limit effort="30" velocity="1.0" lower="-1.570795" upper="1.570795" />
    <origin xyz="0.101 0 0.207" rpy="0 0 0" />
    <axis xyz="0 1 0" />
  </joint>

  <joint name="elbow_joint" type="revolute">
    <parent link="elbow_link" />
    <child link="wrist_link" />
    <limit effort="30" velocity="1.0" lower="-1.570795" upper="1.570795" />
    <origin xyz="-0.014 0.037 0.341" rpy="0 0 0" />
    <axis xyz="0 1 0" />
  </joint>

  <joint name="wrist_joint" type="revolute">
    <parent link="wrist_link" />
    <child link="hand_link" />
    <limit effort="30" velocity="1.0" lower="-1.570795" upper="1.570795" />
    <origin xyz="-0.015 -0.088 0.398" rpy="0 0 0" />
    <axis xyz="0 1 0" />
  </joint>

  <joint name="hand_joint" type="continuous">
    <parent link="hand_link" />
    <child link="gripper_link" />
    <limit effort="30" velocity="1.0" lower="-1.570795" upper="1.570795" />
    <origin xyz="0.0 0.056 0.113" rpy="0 0 0" />
    <axis xyz="0 0 1" />
  </joint>


  <transmission name="tran1">
    <type>transmission_interface/SimpleTransmission</type>
    <joint name="base2base_joint">
      <hardwareInterface>hardware_interface/PositionJointInterface</hardwareInterface>
    </joint>
    <actuator name="motor1">
      <mechanicalReduction>1</mechanicalReduction>
    </actuator>
  </transmission>

  <transmission name="tran2">
    <type>transmission_interface/SimpleTransmission</type>
    <joint name="base_joint">
      <hardwareInterface>hardware_interface/PositionJointInterface</hardwareInterface>
    </joint>
    <actuator name="motor2">
      <mechanicalReduction>1</mechanicalReduction>
    </actuator>
  </transmission>

  <transmission name="tran3">
    <type>transmission_interface/SimpleTransmission</type>
    <joint name="elbow_joint">
      <hardwareInterface>hardware_interface/PositionJointInterface</hardwareInterface>
    </joint>
    <actuator name="motor3">
      <mechanicalReduction>1</mechanicalReduction>
    </actuator>
  </transmission>

  <transmission name="tran4">
    <type>transmission_interface/SimpleTransmission</type>
    <joint name="wrist_joint">
      <hardwareInterface>hardware_interface/PositionJointInterface</hardwareInterface>
    </joint>
    <actuator name="motor4">
      <mechanicalReduction>1</mechanicalReduction>
    </actuator>
  </transmission>

  <transmission name="tran5">
    <type>transmission_interface/SimpleTransmission</type>
    <joint name="hand_joint">
      <hardwareInterface>hardware_interface/PositionJointInterface</hardwareInterface>
    </joint>
    <actuator name="motor5">
      <mechanicalReduction>1</mechanicalReduction>
    </actuator>
  </transmission>


<gazebo>
  <plugin name="gazebo_ros_control" filename="libgazebo_ros_control.so">
  </plugin>
</gazebo>

</robot>
